### 解决问题
当处理第一个异常时，可能会触发第二种异常情况，从而要求抛出第二个异常。遗憾的是，当抛出第二个异常时，正在处理的第一个异常的所有信息都会丢失。C++用嵌套异常（nested exception）的概念提供了解决这一问题的方案，嵌套异常允许将捕获的异常嵌套到新的异常环境。使用std::throw_nested()可以抛出嵌套了异常的异常。第二个异常的catch处理程序可以使用dynamic_cast访问代表第一个异常的nested_exception

##### 简单示例
```cpp
void doSomething(){
	try {
		throw runtime_error("Throwing a runtime_error exception");
	}
	catch (const runtime_error&e) {
		cout << __func__ << " caught a runtime_error" << std::endl;
		cout << __func__ << " throwing MyException" << endl;
		throw_with_nested(MyException("MyException with nested runtimeerror)"));
	}
}

int main()
{
	try {
		doSomething();
	}
	catch (const MyException&e)
	{
		cout << __func__ << " caught MyException: " << e.what() << endl;
		auto *pNested = dynamic_cast<const nested_exception*>(&e);
		if (pNested)
		{
			try
			{
				pNested->rethrow_nested();
			}
			catch (const std::runtime_error& e)
			{
				//handle nested exception
				cout << " Nested exception: " << e.what() << endl;
			}
		}
	}
	return 0;
}

```

关键词throw_with_nested，dynamic_cast<const nested_exception*>(&e)


#### 官方示例
```cpp
#include <iostream>
#include <stdexcept>
#include <exception>
#include <string>
#include <fstream>
 
// prints the explanatory string of an exception. If the exception is nested,
// recurses to print the explanatory of the exception it holds
void print_exception(const std::exception& e, int level =  0)
{
    std::cerr << std::string(level, ' ') << "exception: " << e.what() << '\n';
    try {
        std::rethrow_if_nested(e);
    } catch(const std::exception& e) {
        print_exception(e, level+1);
    } catch(...) {}
}
 
// sample function that catches an exception and wraps it in a nested exception
void open_file(const std::string& s)
{
    try {
        std::ifstream file(s);
        file.exceptions(std::ios_base::failbit);
    } catch(...) {
        std::throw_with_nested( std::runtime_error("Couldn't open " + s) );
    }
}
 
// sample function that catches an exception and wraps it in a nested exception
void run()
{
    try {
        open_file("nonexistent.file");
    } catch(...) {
        std::throw_with_nested( std::runtime_error("run() failed") );
    }
}
 
// runs the sample function above and prints the caught exception
int main()
{
    try {
        run();
    } catch(const std::exception& e) {
        print_exception(e);
    }
}

/** 输出

exception: run() failed
 exception: Couldn't open nonexistent.file
  exception: basic_ios::clear
*/

```